Calling LLM API...
ERROR: LLM API returned an error: ‚ùå ERROR: API call failed: HTTPConnectionPool(host='localhost', port=8000): Max retries exceeded with url: /v1/completions (Caused by NewConnectionError('<urllib3.connection.HTTPConnection object at 0x1503fa19fa10>: Failed to establish a new connection: [Errno 111] Connection refused'))
LLM API call completed successfully!
